<mujoco model="mybipedal_v4">
  <compiler angle='radian' eulerseq="XYZ" meshdir="../meshes"
    autolimits="true" />

  <option timestep="0.005" />

  <visual>
    <global azimuth="150" elevation="-20" />
    <headlight ambient="0.3 0.3 0.3" diffuse="0.6 0.6 0.6" specular="0 0 0" />
    <scale forcewidth="0.03" contactwidth="0.01" contactheight="0.02" com="1" framelength="0.6"
      framewidth="0.05" />
    <rgba haze="0.15 0.25 0.35 1" com="0.502 1 0 0.5" contactpoint="1 1 0.6 0.4"
      contactforce="0.98 0.4 0.4 1" />
  </visual>
  <!-- <statistic extent="1.1" center="0 0 0.55" /> -->
  <default>
      <geom contype = "0" conaffinity = "0" solref = "0.005 1" condim = "3" friction = "1 1" />
      <equality solref = "0.005 1" />
      <default class = "zhiyuan">
      </default>
      <default class = "collision">
          <geom contype = "1" group = "3" type = "capsule" />
          <default class = "collision-left">
              <geom contype = "2" conaffinity = "4" />
          </default>
          <default class = "collision-right">
              <geom contype = "4" conaffinity = "2" />
          </default>
      </default>
    </default>

  <asset>
    <mesh name="base_link" file="base_link.stl" scale="0.001 0.001 0.001"/>
    <mesh name="hip_roll_right_link_1" file="hip_roll_right_link_1.stl" scale="0.001 0.001 0.001"/>
    <mesh name="hip_roll_left_link_1" file="hip_roll_left_link_1.stl" scale="0.001 0.001 0.001"/>
    <mesh name="hip_pitch_right_link_1" file="hip_pitch_right_link_1.stl" scale="0.001 0.001 0.001"/>
    <mesh name="knee_right_link_1" file="knee_right_link_1.stl" scale="0.001 0.001 0.001"/>
    <mesh name="feet_right_link_1" file="feet_right_link_1.stl" scale="0.001 0.001 0.001"/>
    <mesh name="hip_pitch_left_link_1" file="hip_pitch_left_link_1.stl" scale="0.001 0.001 0.001"/>
    <mesh name="knee_left_link_1" file="knee_left_link_1.stl" scale="0.001 0.001 0.001"/>
    <mesh name="feet_left_link_1" file="feet_left_link_1.stl" scale="0.001 0.001 0.001"/>
    <mesh name="RT00_v1__3__1" file="RT00_v1__3__1.stl" scale="0.001 0.001 0.001"/>
    <mesh name="RT00_v1__2__1" file="RT00_v1__2__1.stl" scale="0.001 0.001 0.001"/>
    <mesh name="RS02_v1__1__1" file="RS02_v1__1__1.stl" scale="0.001 0.001 0.001"/>
    <mesh name="RS02_v1_1" file="RS02_v1_1.stl" scale="0.001 0.001 0.001"/>
    <mesh name="RT00_v1__1__1" file="RT00_v1__1__1.stl" scale="0.001 0.001 0.001"/>
    <mesh name="RT00_v1_1" file="RT00_v1_1.stl" scale="0.001 0.001 0.001"/>
    <mesh name="batteryPack_1" file="batteryPack_1.stl" scale="0.001 0.001 0.001"/>
    <mesh name="RS02_v1__3__1" file="RS02_v1__3__1.stl" scale="0.001 0.001 0.001"/>
    <mesh name="RS02_v1__2__1" file="RS02_v1__2__1.stl" scale="0.001 0.001 0.001"/>
  </asset>

  <worldbody>
    <body name="base_link" pos="0 0 0.6">
      <inertial pos="-0.0110299 0.00020768 -0.0602687" quat="0.656642 0.655867 0.264494 -0.26211" mass="0.856205" diaginertia="0.00855945 0.00669559 0.00462196"/>
      <freejoint name="floating_base"/>
      <geom type="mesh" contype="0" conaffinity="0" group="1" density="0" mesh="base_link"/>
      <geom type="mesh" rgba="1 0.4 0.4 1" mesh="base_link" class="collision"/>
      <site name = "imu" size = "0.01" pos = "0.001 0 0" />

      
      <body name="hip_roll_left_link_1" pos="-0.079952 0.083 -0.160122">
        <inertial pos="0.0234792 0.018613 -0.0135553" quat="0.131119 0.473949 0.688546 0.532997" mass="0.0666854" diaginertia="0.000131149 0.000113651 6.62004e-05"/>
        <joint name="left_hip_roll_joint" type='hinge' pos="0 0 0" axis="-0.866025 0 0.5" damping='1' armature="0.1" range="-0.81 0.22" actuatorfrcrange="-14 14"/>
        <geom pos="0.079952 -0.083 0.160122" quat="1 0 0 0" type="mesh" contype="0" conaffinity="0" group="1" density="0" mesh="hip_roll_left_link_1"/>
        <geom pos="0.079952 -0.083 0.160122" quat="1 0 0 0" type="mesh" mesh="hip_roll_left_link_1" rgba="1 1 0.4 1"/>
        <body name="hip_pitch_left_link_1" pos="0.054993 0.031 -0.03175">
          <inertial pos="0.0125517 -0.0304827 -0.0225734" quat="0.701463 -0.165617 -0.141083 0.678687" mass="0.12802" diaginertia="0.000386371 0.000376345 0.000167284"/>
          <joint name="left_hip_pitch_joint" type='hinge' pos="0 0 0" axis="0 -1 0" damping='1' armature="0.1" range="-1.57 1.24" actuatorfrcrange="-17 17"/>
          <geom pos="0.024959 -0.114 0.191872" quat="1 0 0 0" type="mesh" contype="0" conaffinity="0" group="1" density="0" mesh="hip_pitch_left_link_1"/>
          <geom pos="0.024959 -0.114 0.191872" quat="1 0 0 0" type="mesh" mesh="hip_pitch_left_link_1" rgba="0 0.5 1 1"/>
          <body name="knee_left_link_1" pos="0.040571 -0.015 -0.087005">
            <inertial pos="-0.0117138 -0.0169493 -0.0672482" quat="0.702201 0.0831503 0.0831503 0.702201" mass="0.0961872" diaginertia="0.000414 0.000388735 4.52647e-05"/>
            <joint name="left_knee_joint" type='hinge' pos="0 0 0" axis="0 -1 0" damping='1' armature="0.1" range="-1.17 0.3" actuatorfrcrange="-17 17"/>
            <geom pos="-0.015612 -0.099 0.278877" quat="1 0 0 0" type="mesh" contype="0" conaffinity="0" group="1" density="0" mesh="knee_left_link_1"/>
            <geom pos="-0.015612 -0.099 0.278877" quat="1 0 0 0" type="mesh" mesh="knee_left_link_1" rgba="0.4 1 0.4 1"/>
            <body name="feet_left_link_1" pos="-0.031881 -0.01 -0.168826">
              <inertial pos="-0.00136027 -0.00691159 -0.0225652" quat="0 0.720547 0 0.693406" mass="0.0567994" diaginertia="9.61152e-05 9.3e-05 1.78848e-05"/>
              <joint name="left_ankle_joint" type='hinge' pos="0 0 0" axis="0 -1 0" damping='1' armature="0.1" range="-0.57 0.85" actuatorfrcrange="-14 14"/>
              <geom pos="0.016269 -0.089 0.447703" quat="1 0 0 0" type="mesh" contype="0" conaffinity="0" group="1" density="0" mesh="feet_left_link_1"/>
              <geom pos="0.016269 -0.089 0.447703" quat="1 0 0 0" type="mesh" mesh="feet_left_link_1" rgba="0.8 1.0 0.8 1"/>
              <geom type = "sphere" size = "0.015" pos = "0.069 0.01 -0.02" class = "collision"  />
              <geom type = "sphere" size = "0.015" pos = "0.069 -0.023 -0.02" class = "collision"  />
              <geom type = "sphere" size = "0.015" pos = "-0.063 0.01 -0.02" class = "collision"  />
              <geom type = "sphere" size = "0.015" pos = "-0.063 -0.023 -0.02" class = "collision"  />
              <geom type = "sphere" size = "0.01" pos = "0.069 0.01 -0.02" rgba = "255 0 0 0.5"  />
              <geom type = "sphere" size = "0.01" pos = "0.069 -0.023 -0.02" rgba = "255 0 0 0.5"  />
              <geom type = "sphere" size = "0.01" pos = "-0.063 0.01 -0.02" rgba = "255 0 0 0.5"  />
              <geom type = "sphere" size = "0.01" pos = "-0.063 -0.023 -0.02" rgba = "255 0 0 0.5"  />
            </body>
            <body name="RT00_v1_1" pos="-0.015731 -0.0065 -0.064007">
              <inertial pos="0.000345816 -0.0222804 -7.4374e-05" quat="0.5 0.5 -0.5 0.5" mass="0.325391" diaginertia="0.000192 0.000189 0.000176"/>
              <geom pos="0.000119 -0.0925 0.342884" quat="1 0 0 0" type="mesh" contype="0" conaffinity="0" group="1" density="0" mesh="RT00_v1_1"/>
              <geom pos="0.000119 -0.0925 0.342884" quat="1 0 0 0" type="mesh" mesh="RT00_v1_1"/>
            </body>
          </body>
          <body name="RS02_v1_1" pos="0 -0.062 0">
            <inertial pos="0.000714323 -0.0190126 0.00109074" quat="0.634494 0.303427 0.306163 0.641571" mass="0.365186" diaginertia="0.000338011 0.000252654 0.000238335"/>
            <geom pos="0.024959 -0.052 0.191872" quat="1 0 0 0" type="mesh" contype="0" conaffinity="0" group="1" density="0" mesh="RS02_v1_1"/>
            <geom pos="0.024959 -0.052 0.191872" quat="1 0 0 0" type="mesh" mesh="RS02_v1_1"/>
          </body>
        </body>
        <body name="RS02_v1__3__1" pos="0.054993 0.046 -0.03175">
          <inertial pos="0.000616559 0.0190126 -0.00114842" quat="0.283581 0.651911 0.644669 0.281062" mass="0.365186" diaginertia="0.000338011 0.000252512 0.000238477"/>
          <geom pos="0.024959 -0.129 0.191872" quat="1 0 0 0" type="mesh" contype="0" conaffinity="0" group="1" density="0" mesh="RS02_v1__3__1"/>
          <geom pos="0.024959 -0.129 0.191872" quat="1 0 0 0" type="mesh" mesh="RS02_v1__3__1"/>
        </body>
      </body>
      <body name="hip_roll_right_link_1" pos="-0.079952 -0.083 -0.160122">
        <inertial pos="0.0234791 -0.018613 -0.0135553" quat="0.532997 0.688546 0.473949 0.131119" mass="0.0666853" diaginertia="0.000131149 0.000113651 6.62004e-05"/>
        <joint name="right_hip_roll_joint" type='hinge' pos="0 0 0" axis="-0.866025 0 0.5" damping='1' armature="0.1" range="-0.22 0.81" actuatorfrcrange="-14 14"/>
        <geom pos="0.079952 0.083 0.160122" quat="1 0 0 0" type="mesh" contype="0" conaffinity="0" group="1" density="0" mesh="hip_roll_right_link_1"/>
        <geom pos="0.079952 0.083 0.160122" quat="1 0 0 0" type="mesh" mesh="hip_roll_right_link_1" rgba="1 1 0.4 1"/>
        <body name="hip_pitch_right_link_1" pos="0.054993 -0.031 -0.03175">
          <inertial pos="0.0127994 0.0307163 -0.0230654" quat="0.649645 -0.150004 -0.155989 0.728785" mass="0.126875" diaginertia="0.00038635 0.000376054 0.000166596"/>
          <joint name="right_hip_pitch_joint" type='hinge' pos="0 0 0" axis="0 -1 0" damping='1' armature="0.1" range="-1.57 1.24" actuatorfrcrange="-17 17"/>
          <geom pos="0.024959 0.114 0.191872" quat="1 0 0 0" type="mesh" contype="0" conaffinity="0" group="1" density="0" mesh="hip_pitch_right_link_1"/>
          <geom pos="0.024959 0.114 0.191872" quat="1 0 0 0" type="mesh" mesh="hip_pitch_right_link_1" rgba="0 0.5 1 1"/>
          <body name="knee_right_link_1" pos="0.040571 0.015 -0.087005">
            <inertial pos="-0.0117137 0.0169493 -0.067248" quat="0.702201 0.0831503 0.0831503 0.702201" mass="0.0961875" diaginertia="0.000414 0.000388735 4.52647e-05"/>
            <joint name="right_knee_joint" type='hinge' pos="0 0 0" axis="0 -1 0" damping='1' armature="0.1" range="-1.17 0.3" actuatorfrcrange="-17 17"/>
            <geom pos="-0.015612 0.099 0.278877" quat="1 0 0 0" type="mesh" contype="0" conaffinity="0" group="1" density="0" mesh="knee_right_link_1"/>
            <geom pos="-0.015612 0.099 0.278877" quat="1 0 0 0" type="mesh" mesh="knee_right_link_1" rgba="0.4 1 0.4 1"/>
            <body name="feet_right_link_1" pos="-0.031881 0.01 -0.168826">
              <inertial pos="-0.00136027 0.00691158 -0.0225652" quat="0 0.720547 0 0.693406" mass="0.0567994" diaginertia="9.61152e-05 9.3e-05 1.78848e-05"/>
              <joint name="right_ankle_joint" type='hinge' pos="0 0 0" axis="0 -1 0" damping='1' armature="0.1" range="-0.57 0.85" actuatorfrcrange="-14 14"/>
              <geom pos="0.016269 0.089 0.447703" quat="1 0 0 0" type="mesh" contype="0" conaffinity="0" group="1" density="0" mesh="feet_right_link_1"/>
              <geom pos="0.016269 0.089 0.447703" quat="1 0 0 0" type="mesh" mesh="feet_right_link_1" rgba="0.8 1.0 0.8 1" />
              <geom type = "sphere" size = "0.015" pos = "0.069 0.023 -0.02" class = "collision"  />
              <geom type = "sphere" size = "0.015" pos = "0.069 -0.01 -0.02" class = "collision"  />
              <geom type = "sphere" size = "0.015" pos = "-0.063 0.023 -0.02" class = "collision"  />
              <geom type = "sphere" size = "0.015" pos = "-0.063 -0.01 -0.02" class = "collision"  />
              <geom type = "sphere" size = "0.01" pos = "0.069 0.023 -0.02" rgba = "255 0 0 0.5"  />
              <geom type = "sphere" size = "0.01" pos = "0.069 -0.01 -0.02" rgba = "255 0 0 0.5"  />
              <geom type = "sphere" size = "0.01" pos = "-0.063 0.023 -0.02" rgba = "255 0 0 0.5"  />
              <geom type = "sphere" size = "0.01" pos = "-0.063 -0.01 -0.02" rgba = "255 0 0 0.5"  />
            </body>
            <body name="RT00_v1__1__1" pos="-0.015731 0.0065 -0.064007">
              <inertial pos="-0.000350568 0.0222804 4.84174e-05" quat="0.567843 0.567843 -0.421372 0.421372" mass="0.325391" diaginertia="0.000192303 0.000188697 0.000176"/>
              <geom pos="0.000119 0.0925 0.342884" quat="1 0 0 0" type="mesh" contype="0" conaffinity="0" group="1" density="0" mesh="RT00_v1__1__1"/>
              <geom pos="0.000119 0.0925 0.342884" quat="1 0 0 0" type="mesh" mesh="RT00_v1__1__1"/>
            </body>
          </body>
          <body name="RS02_v1__1__1" pos="0 0.062 0">
            <inertial pos="0.0012945 0.0190126 -0.000153445" quat="0.551354 0.448204 0.437663 0.550975" mass="0.365186" diaginertia="0.000338021 0.000252652 0.000238327"/>
            <geom pos="0.024959 0.052 0.191872" quat="1 0 0 0" type="mesh" contype="0" conaffinity="0" group="1" density="0" mesh="RS02_v1__1__1"/>
            <geom pos="0.024959 0.052 0.191872" quat="1 0 0 0" type="mesh" mesh="RS02_v1__1__1"/>
          </body>
        </body>
        <body name="RS02_v1__2__1" pos="0.054993 -0.046 -0.03175">
          <inertial pos="0.00130296 -0.0190126 4.04714e-05" quat="0.415956 0.567545 0.568376 0.426406" mass="0.365186" diaginertia="0.000338021 0.000253206 0.000238773"/>
          <geom pos="0.024959 0.129 0.191872" quat="1 0 0 0" type="mesh" contype="0" conaffinity="0" group="1" density="0" mesh="RS02_v1__2__1"/>
          <geom pos="0.024959 0.129 0.191872" quat="1 0 0 0" type="mesh" mesh="RS02_v1__2__1"/>
        </body>
      </body>
      <body name="RT00_v1__3__1" pos="-0.090777 -0.083 -0.153872">
        <inertial pos="-0.0193021 -0.000353565 0.0111291" quat="0 0.866581 0 0.499036" mass="0.325391" diaginertia="0.000192062 0.000189 0.000175938"/>
        <geom pos="0.090777 0.083 0.153872" quat="1 0 0 0" type="mesh" contype="0" conaffinity="0" group="1" density="0" mesh="RT00_v1__3__1"/>
        <geom pos="0.090777 0.083 0.153872" quat="1 0 0 0" type="mesh" mesh="RT00_v1__3__1"/>
      </body>
      <body name="RT00_v1__2__1" pos="-0.090777 0.083 -0.153872">
        <inertial pos="-0.0193021 -0.000353565 0.0111291" quat="0 0.866581 0 0.499036" mass="0.325391" diaginertia="0.000192062 0.000189 0.000175938"/>
        <geom pos="0.090777 -0.083 0.153872" quat="1 0 0 0" type="mesh" contype="0" conaffinity="0" group="1" density="0" mesh="RT00_v1__2__1"/>
        <geom pos="0.090777 -0.083 0.153872" quat="1 0 0 0" type="mesh" mesh="RT00_v1__2__1"/>
      </body>
      <body name="batteryPack_1" pos="-0.009 0 -0.065">
        <inertial pos="0.0105614 -1.9471e-05 -0.0308043" quat="0 0.719548 0 0.694443" mass="0.550064" diaginertia="0.000894604 0.000802 0.000415396"/>
        <geom pos="0.009 0 0.065" quat="1 0 0 0" type="mesh" contype="0" conaffinity="0" group="1" density="0" mesh="batteryPack_1"/>
        <geom pos="0.009 0 0.065" quat="1 0 0 0" type="mesh" mesh="batteryPack_1"/>
      </body>
    </body>
  </worldbody>

  <actuator>
    <motor name = 'motor_left_hip_roll_joint' joint = 'left_hip_roll_joint' gear="1" ctrlrange = '-14 14' />
    <motor name = 'motor_right_hip_roll_joint' joint = 'right_hip_roll_joint' gear="1" ctrlrange = '-14 14' />
    <motor name = 'motor_left_hip_pitch_joint' joint = 'left_hip_pitch_joint' gear="1" ctrlrange = '-17 17' />
    <motor name = 'motor_right_hip_pitch_joint' joint = 'right_hip_pitch_joint' gear="1" ctrlrange = '-17 17' />
    <motor name = 'motor_left_knee_joint' joint = 'left_knee_joint' gear="1" ctrlrange = '-17 17' />
    <motor name = 'motor_right_knee_joint' joint = 'right_knee_joint' gear="1" ctrlrange = '-17 17' />
    <motor name = 'motor_left_ankle_joint' joint = 'left_ankle_joint' gear="1" ctrlrange = '-14 14' />
    <motor name = 'motor_right_ankle_joint' joint = 'right_ankle_joint' gear="1" ctrlrange = '-14 14' />
  </actuator>

    <sensor>
    <!-- imu sensor -->
    <framequat name="body-orientation" objtype="site" objname="imu" noise="0"/>
    <gyro name="body-angular-velocity" site="imu" noise="0.001"/>
    <framepos name="body-linear-pos" objtype="site" objname="imu"/>
    <velocimeter name="body-linear-vel" site="imu"/>
    <accelerometer name="body-linear-acceleration" site="imu" noise="0.001"/>

    <jointpos name = 'jointpos_left_hip_roll_joint' joint = 'left_hip_roll_joint' noise = "0" />
    <jointpos name = 'jointpos_left_hip_pitch_joint' joint = 'left_hip_pitch_joint' noise = "0" />
    <jointpos name = 'jointpos_left_knee_joint' joint = 'left_knee_joint' noise = "0" />
    <jointpos name = 'jointpos_left_ankle_joint' joint = 'left_ankle_joint' noise = "0" />


    <jointpos name = 'jointpos_right_hip_roll_joint' joint = 'right_hip_roll_joint' noise = "0" />
    <jointpos name = 'jointpos_right_hip_pitch_joint' joint = 'right_hip_pitch_joint' noise = "0" />
    <jointpos name = 'jointpos_right_knee_joint' joint = 'right_knee_joint' noise = "0" />
    <jointpos name = 'jointpos_right_ankle_joint' joint = 'right_ankle_joint' noise = "0" />


    <jointvel name = 'jointvel_left_hip_roll_joint' joint = 'left_hip_roll_joint' noise = "0" />
    <jointvel name = 'jointvel_left_hip_pitch_joint' joint = 'left_hip_pitch_joint' noise = "0" />
    <jointvel name = 'jointvel_left_knee_joint' joint = 'left_knee_joint' noise = "0" />
    <jointvel name = 'jointvel_left_ankle_joint' joint = 'left_ankle_joint' noise = "0" />


    <jointvel name = 'jointvel_right_hip_roll_joint' joint = 'right_hip_roll_joint' noise = "0" />
    <jointvel name = 'jointvel_right_hip_pitch_joint' joint = 'right_hip_pitch_joint' noise = "0" />
    <jointvel name = 'jointvel_right_knee_joint' joint = 'right_knee_joint' noise = "0" />
    <jointvel name = 'jointvel_right_ankle_joint' joint = 'right_ankle_joint' noise = "0" />

  </sensor>


  <keyframe>
    <key name = "home_default" qpos = "0 0 0.9 1 0 0 0 0. 0. 0. 0. 0. 0. 0. 0."/>
  </keyframe>

</mujoco>
